Workbook

Sheet 1. Executive Summary
B2: Comprehensive Financial Plan
B3: Mitchell Household — Prepared October 2026
B5: Case study for educational use. Not investment, tax, legal, or insurance advice. Recommendations are illustrative and based on stated assumptions.
B8: CLIENT SNAPSHOT
B9: Client | C9: Sarah Mitchell
B10: Spouse | C10: Michael Mitchell
B11: Ages | C11: 38 / 36
B12: Location | C12: Tyler, Texas
B13: Household Income | C13: $172,000
B14: Business | C14: East Texas Landscaping & Design LLC
B15: Dependents | C15: 2 children (ages 8, 11)
B16: Plan Date | C16: October 2026
B19: KEY FINANCIAL METRICS
B20: Net Worth | C20: Monthly Net Cash Flow | D20: Current Savings Rate | E20: Emergency Fund (months) | F20: Retirement Savings | G20: Retirement Funding Gap
B21: ='5. Net Worth'!J1 -> 323500 | C21: ='4. Cash Flow'!J1 -> 5935 | D21: ='4. Cash Flow'!J2 -> 0.059259259 | E21: ='6. Debt & Liquidity'!J1 -> 1.9828156 | F21: ='7. Retirement'!J1 -> 120000 | G21: ='7. Retirement'!J2 -> 174617.9
B23: KEY RECOMMENDATIONS
B24: Recommendation | C24: Description | E24: Timeline
B25: 1. Emergency Fund | C25: Increase reserves from $15K to $45K (6 months) over 18 months | E25: HIGH | F25: 0-6 months
B26: 2. Retirement Plan | C26: Establish SEP IRA for the business; increase total savings to $25K/yr | E26: HIGH | F26: 0-6 months
B27: 3. Debt Payoff | C27: Pay off $8,500 credit card debt within 6 months using avalanche method | E27: HIGH | F27: 0-6 months
B28: 4. Life Insurance | C28: Purchase $1.25M term life on Sarah + $750K on Michael | E28: HIGH | F28: 0-6 months
B29: 5. Disability | C29: Obtain disability income insurance (business overhead + personal) | E29: MEDIUM | F29: 6-12 months
B30: 6. College Savings | C30: Open 529 plans for both children; contribute $400/month total | E30: MEDIUM | F30: 6-12 months
B31: 7. Tax Strategy | C31: Implement quarterly tax reserves; explore S-Corp election | E31: MEDIUM | F31: 6-12 months
B32: 8. Investment Review | C32: Rebalance IRA to 80/20 equity/bond target allocation | E32: LOW | F32: 12+ months

Sheet 2. Client Profile
B2: Client Profile & Financial Goals
B3: Mitchell Household
B5: PRIMARY CLIENT | E5: SPOUSE
B6: Name | C6: Sarah Mitchell | E6: Name | F6: Michael Mitchell
B7: Age | C7: 38 | E7: Age | F7: 36
B8: Occupation | C8: Business Owner | E8: Occupation | F8: Middle School Teacher
B9: Business | C9: East Texas Landscaping & Design LLC | E9: Employer | F9: Tyler ISD
B10: Entity Type | C10: Single-member LLC (Sch. C) | E10: W-2 Income | F10: 52000
B11: Years in Business | C11: 6 | E11: Health Status | F11: Good
B12: Health Status | C12: Good | E12: Retirement Age | F12: 60
B13: Retirement Age Target | C13: 67
B15: DEPENDENTS
B16: Child 1 | C16: Emma Mitchell, Age 8
B17: Child 2 | C17: Jacob Mitchell, Age 11
B19: BUSINESS OVERVIEW
B20: Item | C20: Value | D20: Notes
B21: Business Name | C21: East Texas Landscaping & Design LLC
B22: Entity Type | C22: Single-member LLC (taxed as sole proprietor)
B23: Years Operating | C23: 6
B24: Annual Revenue | C24: 450000
B25: Annual Expenses (incl. payroll) | C25: 310000
B26: Net Business Income | C26: =C24-C25 -> 140000
B27: Number of Employees | C27: 2 | D27: (part-time)
B28: Owner's Draw (annual) | C28: 120000
B29: Business Assets (equipment) | C29: 120000
B30: Business Debt (equipment loan) | C30: 28000
B32: FINANCIAL GOALS
B33: # | C33: Goal | D33: Target Amount | E33: Timeline | F33: Priority
B34: 1 | C34: Build emergency fund (6 months) | D34: 45000 | E34: 18 months | F34: Critical
B35: 2 | C35: Pay off credit card debt | D35: 8500 | E35: 6 months | F35: Critical
B36: 3 | C36: Establish SEP IRA for business | D36: 22500 | E36: Immediate | F36: Critical
B37: 4 | C37: Purchase $1.25M term life on Sarah + $750K on Michael | D37: 50000 | E37: 3 months | F37: High
B38: 5 | C38: Open 529 college savings plans | D38: 4800 | E38: 3 months | F38: Medium
B39: 6 | C39: Increase retirement savings to $25K/yr | D39: 25000 | E39: 12 months | F39: High
B40: 7 | C40: Business succession plan | D40: 0 | E40: 2-3 years | F40: Medium
B41: 8 | C41: Pay off equipment loan early | D41: 28000 | E41: 24 months | F41: Low

Sheet 3. Assumptions
B2: Planning Assumptions
B3: All projections in this plan are based on these inputs
B5: RETURN & ECONOMIC ASSUMPTIONS
B6: Assumption | C6: Value | E6: Notes
B7: Inflation rate (CPI) | C7: 0.03 | E7: Long-term CPI average ~3.0%
B8: Conservative investment return | C8: 0.05 | E8: Conservative: 60/40 equity/bond blend
B9: Base case investment return | C9: 0.07 | E9: Base: 80/20 equity/bond blend (target)
B10: Optimistic investment return | C10: 0.09 | E10: Optimistic: 90/10 equity/bond blend
B11: Retirement withdrawal rate | C11: 0.04 | E11: 4% safe withdrawal rate (Bengen rule)
B12: College cost inflation | C12: 0.05 | E12: 529 plan average cost growth
B13: Social Security COLA (avg) | C13: 0.025 | E13: Historical SS COLA average
B14: Income growth rate (annual) | C14: 0.035 | E14: Moderate income growth assumption
B15: Mortgage interest rate | C15: 0.0575 | E15: Current 30-yr fixed (obtained 2023)
B16: Marginal tax rate (federal) | C16: 0.24 | E16: Federal bracket for $172K MFJ
B17: Self-employment tax rate | C17: 0.153 | E17: Social Security + Medicare tax
B18: Texas state income tax | C18: 0 | E18: Texas has no state income tax
B20: RETIREMENT PLAN ASSUMPTIONS
B21: Assumption | C21: Value
B22: Sarah's retirement age | C22: 67
B23: Michael's retirement age | C23: 60
B24: Years to Sarah's retirement | C24: 29
B25: Sarah's Social Security (age 67) | C25: 32000
B26: Michael's pension (Teacher Retirement) | C26: 36000
B27: Michael's Social Security (age 67) | C27: 24000
B28: Target retirement income (today's $) | C28: 80000
B30: LEGEND
B31: Blue text | C31: Hard-coded input / assumption
B32: Black text | C32: Calculated formula or function
B33: Green text | C33: Direct link to another sheet
B34: Yellow fill | C34: Key assumption (change to update projections)

Sheet 4. Cash Flow
J1: =C32 -> 5935
B2: Cash Flow Analysis | J2: =(C36+C37)/C10 -> 0.059259259
B3: Monthly and annual income vs. expenses
B5: MONTHLY INCOME
B6: Source | C6: Monthly | D6: Annual | E6: After-Tax Monthly
B7: Sarah's owner draw (avg) | C7: 10000 | D7: 120000
B8: Michael's W-2 (gross) | C8: 4333 | D8: 52000
B9: Michael's W-2 (after-tax est.) | C9: 3500 | D9: 42000 | E9: =C9 -> 3500
B10: Total Household Income (after-tax) | C10: =C7+C9 -> 13500 | D10: =D7+D9 -> 162000 | E10: =C10 -> 13500
B12: MONTHLY EXPENSES
B13: Category | C13: Monthly | D13: Annual | E13: % of Income
B14: Mortgage (P&I) | C14: 1668 | D14: =C14*12 -> 20016 | E14: =C14/$C$10 -> 0.12355556
B15: Property taxes | C15: 450 | D15: =C15*12 -> 5400 | E15: =C15/$C$10 -> 0.033333333
B16: Home insurance | C16: 150 | D16: =C16*12 -> 1800 | E16: =C16/$C$10 -> 0.011111111
B17: Utilities (electric, water, gas) | C17: 350 | D17: =C17*12 -> 4200 | E17: =C17/$C$10 -> 0.025925926
B18: Internet & phone | C18: 180 | D18: =C18*12 -> 2160 | E18: =C18/$C$10 -> 0.013333333
B19: Groceries & household | C19: 1200 | D19: =C19*12 -> 14400 | E19: =C19/$C$10 -> 0.088888889
B20: Auto payment 1 | C20: 412 | D20: =C20*12 -> 4944 | E20: =C20/$C$10 -> 0.030518519
B21: Auto payment 2 | C21: 385 | D21: =C21*12 -> 4620 | E21: =C21/$C$10 -> 0.028518519
B22: Auto insurance | C22: 220 | D22: =C22*12 -> 2640 | E22: =C22/$C$10 -> 0.016296296
B23: Fuel / transportation | C23: 400 | D23: =C23*12 -> 4800 | E23: =C23/$C$10 -> 0.02962963
B24: Childcare / after-school | C24: 600 | D24: =C24*12 -> 7200 | E24: =C24/$C$10 -> 0.044444444
B25: Children's activities | C25: 300 | D25: =C25*12 -> 3600 | E25: =C25/$C$10 -> 0.022222222
... B29: Clothing | C29: 200 | D29: =C29*12 -> 2400 | E29: =C29/$C$10 -> 0.014814815
B30: Total Expenses | C30: =SUM(C14:C29) -> 7565 | D30: =SUM(D14:D29) -> 90780 | E30: =C30/$C$10 -> 0.56037037
B32: Net Cash Flow (after-tax) | C32: =C10-C30 -> 5935 | D32: =D10-D30 -> 71220 | E32: =C32/$C$10 -> 0.43962963
B34: CURRENT SAVINGS ALLOCATION
B35: Savings Target | C35: Monthly | D35: Annual | E35: Status
B36: Emergency fund contribution | C36: 500 | D36: =C36*12 -> 6000 | E36: In progress
B37: Michael's 403(b) contribution | C37: 300 | D37: =C37*12 -> 3600 | E37: Ongoing
B38: Credit card debt paydown | C38: 500 | D38: =C38*12 -> 6000 | E38: 6-month plan
B39: Discretionary savings | C39: 2000 | D39: =C39*12 -> 24000 | E39: Unallocated
B41: SAVINGS RATE SUMMARY
B42: Metric | C42: Value
B43: Current savings rate | C43: =(C36+C37)/C10 -> 0.059259259
B44: Recommended savings rate | C44: 0.15
B45: Current total savings (monthly) | C45: =C36+C37 -> 800
B46: Recommended total savings (monthly) | C46: =C10*0.15 -> 2025
B47: Additional savings needed (monthly) | C47: =(C10*0.15)-(C36+C37) -> 1225
B50: Chart Data
...

Sheet 5. Net Worth
J1: =D26 -> 323500
B2: Net Worth Statement
B3: Assets, liabilities, and net worth — as of October 2026
B5: ASSETS
B6: Asset | C6: Current Value | D6: Liquid? | E6: % of Total
B7: Checking account | C7: 5000 | D7: Yes | E7: =C7/$C$15 -> 0.0074074074
B8: Savings (emergency fund) | C8: 15000 | D8: Yes | E8: =C8/$C$15 -> 0.022222222
B9: Sarah's Traditional IRA | C9: 85000 | D9: Yes | E9: =C9/$C$15 -> 0.12592593
B10: Michael's 403(b) | C10: 35000 | D10: Yes | E10: =C10/$C$15 -> 0.051851852
B11: 529 College Savings | C11: 0 | D11: Yes | E11: =C11/$C$15 -> 0
B12: Home (market value) | C12: 380000 | D12: No | E12: =C12/$C$15 -> 0.56296296
B13: Business equipment | C13: 120000 | D13: No | E13: =C13/$C$15 -> 0.17777778
B14: Vehicles (2) | C14: 35000 | D14: No | E14: =C14/$C$15 -> 0.051851852
B15: Total Assets | C15: =SUM(C7:C14) -> 675000 | E15: =SUM(E7:E14) -> 1
B17: LIABILITIES
B18: Liability | C18: Balance | D18: Interest Rate | E18: % of Total
B19: Mortgage | C19: 285000 | D19: 0.0575 | E19: =C19/$C$24 -> 0.81081081
B20: Equipment loan (business) | C20: 28000 | D20: 0.075 | E20: =C20/$C$24 -> 0.079658606
B21: Auto loan 1 | C21: 18000 | D21: 0.065 | E21: =C21/$C$24 -> 0.051209104
B22: Auto loan 2 | C22: 12000 | D22: 0.059 | E22: =C22/$C$24 -> 0.034139403
B23: Credit cards | C23: 8500 | D23: 0.229 | E23: =C23/$C$24 -> 0.024182077
B24: Total Liabilities | C24: =SUM(C19:C23) -> 351500 | E24: =SUM(E19:E23) -> 1
B26: NET WORTH | D26: =C15-C24 -> 323500 | E26: =D26/C15 -> 0.47925926
B27: (Net Worth = Total Assets - Total Liabilities)
B29: KEY RATIOS
B30: Ratio | C30: Value | D30: Target | E30: Status
B31: Debt-to-Asset Ratio | C31: =C24/C15 -> 0.52074074 | D31: 0.5 | E31: =IF(C31>=D31,"On Track","Below Target") -> On Track
B32: Current Ratio (liquid assets / current liab.) | C32: =(C7+C8+C9+C10+C11)/C23 -> 16.470588 | D32: 2 | E32: =IF(C32>=D32,"On Track","Below Target") -> On Track
B33: Net Worth to Income | C33: =D26/('4. Cash Flow'!D10) -> 1.9969136 | D33: 3 | E33: =IF(C33>=D33,"On Track","Below Target") -> Below Target
B34: Liquid Assets to Annual Expenses | C34: =(C7+C8+C9+C10+C11)/('4. Cash Flow'!D30) -> 1.5421899 | D34: 0.5 | E34: =IF(C34>=D34,"On Track","Below Target") -> On Track
B37: Chart Data: Assets
B38: Asset | C38: Value
B39: Cash & Savings | C39: =C7+C8 -> 20000
B40: Retirement Accounts | C40: =C9+C10 -> 120000
B41: Home | C41: =C12 -> 380000
B42: Business Assets | C42: =C13 -> 120000
B43: Vehicles | C43: =C14 -> 35000
B44: 529 Plans | C44: =C11 -> 0

Sheet 6. Debt & Liquidity
J1: =C20 -> 1.9828156
B2: Debt Management & Liquidity Analysis
B3: Debt payoff strategy and emergency fund review
B5: DEBT SUMMARY
B6: Debt | C6: Balance | D6: APR | E6: Min. Payment | F6: Months to Payoff | G6: Total Interest | H6: Payoff Order
B7: Credit cards | C7: 8500 | D7: 0.229 | E7: 250 | F7: =NPER(D7/12,-E7,C7) -> 55.35973 | G7: =E7*F7-C7 -> 5339.9324 | H7: 1
B8: Auto loan 2 | C8: 12000 | D8: 0.059 | E8: 385 | F8: =NPER(D8/12,-E8,C8) -> 33.91618 | G8: =E8*F8-C8 -> 1057.7294 | H8: 2
B9: Auto loan 1 | C9: 18000 | D9: 0.065 | E9: 412 | F9: =NPER(D9/12,-E9,C9) -> 49.988302 | G9: =E9*F9-C9 -> 2595.1806 | H9: 3
B10: Equipment loan | C10: 28000 | D10: 0.075 | E10: 712 | F10: =NPER(D10/12,-E10,C10) -> 45.273664 | G10: =E10*F10-C10 -> 4234.8489 | H10: 4
B11: Mortgage | C11: 285000 | D11: 0.0575 | E11: 1668 | F11: =NPER(D11/12,-E11,C11) -> 357.24537 | G11: =E11*F11-C11 -> 310885.28 | H11: 5
B12: Total Debt | C12: =SUM(C7:C11) -> 351500 | E12: =SUM(E7:E11) -> 3427 | G12: =SUM(G7:G11) -> 324112.97
B14: Strategy: Debt Avalanche — Pay highest-interest debts first (credit cards → equipment loan → auto loans)
B16: EMERGENCY FUND ANALYSIS
B17: Metric | C17: Value | D17: Target | E17: Gap
B18: Current emergency fund | C18: =('5. Net Worth'!C8) -> 15000 | D18: 45000 | E18: =D18-C18 -> 30000
B19: Monthly expenses (total) | C19: ='4. Cash Flow'!C30 -> 7565
B20: Current months covered | C20: =C18/C19 -> 1.9828156 | D20: 6 | E20: =D20-C20 -> 4.0171844
B21: Monthly contribution (current) | C21: 500
B22: Months to reach target | C22: =(D18-C18)/C21 -> 60
B24: RECOMMENDED ACTION
B25: 1. Allocate $2,000/month to emergency fund (increase from $500/month)
B26: 2. Dedicate $1,500/month to credit card paydown (paid off in ~6 months)
B27: 3. After credit cards are paid off, redirect $1,500/month to emergency fund
B28: 4. Target: $45,000 emergency fund (6 months expenses) within 18 months
B29: 5. Maintain separate business emergency fund ($15,000) for business operations

Sheet 7. Retirement
J1: =D9 -> 120000
B2: Retirement Projection Analysis | J2: =C19-F55 -> 174617.9
B3: Current path vs. recommended savings — 3 scenarios
B5: CURRENT RETIREMENT SAVINGS
B6: Account | C6: Owner | D6: Balance
B7: Sarah's Traditional IRA | C7: Sarah | D7: 85000
B8: Michael's 403(b) | C8: Michael | D8: 35000
B9: Total Current Savings | D9: =SUM(D7:D8) -> 120000
B11: PROJECTION ASSUMPTIONS
B12: Parameter | C12: Value | D12: Notes
B13: Years to retirement | C13: 29 | D13: Age 38 to 67
B14: Current annual contribution | C14: 5400 | D14: $3,600 403(b) + $1,800 IRA
B15: Recommended annual contribution | C15: 25000 | D15: SEP IRA + 403(b) max
B16: Conservative return | C16: 0.05 | D16: 60/40 portfolio
B17: Base return | C17: 0.07 | D17: 80/20 portfolio (target)
B18: Optimistic return | C18: 0.09 | D18: 90/10 portfolio
B19: Target retirement fund | C19: 1500000 | D19: $60K/yr @ 4% withdrawal
B21: RETIREMENT PROJECTION (YEAR-BY-YEAR)
B22: Year | C22: Age | D22: Conservative | E22: Base Case | F22: Optimistic | G22: Current Path | H22: Target
B23: 0 | C23: =B23+38 -> 38 | D23: =$D$9 -> 120000 | E23: =$D$9 -> 120000 | F23: =$D$9 -> 120000 | G23: =$D$9 -> 120000 | H23: =$C$19 -> 1500000
B24: 1 | C24: =B24+38 -> 39 | D24: =D23*(1+$C$16)+$C$15 -> 151000 | E24: =E23*(1+$C$17)+$C$15 -> 153400 | F24: =F23*(1+$C$18)+$C$15 -> 155800 | G24: =G23*(1+$C$17)+$C$14 -> 133800 | H24: =$C$19 -> 1500000
B25: 2 | C25: =B25+38 -> 40 | D25: =D24*(1+$C$16)+$C$15 -> 183550 | E25: =E24*(1+$C$17)+$C$15 -> 189138 | F25: =F24*(1+$C$18)+$C$15 -> 194822 | G25: =G24*(1+$C$17)+$C$14 -> 148566 | H25: =$C$19 -> 1500000
B26: 3 | C26: =B26+38 -> 41 | D26: =D25*(1+$C$16)+$C$15 -> 217727.5 | E26: =E25*(1+$C$17)+$C$15 -> 227377.66 | F26: =F25*(1+$C$18)+$C$15 -> 237355.98 | G26: =G25*(1+$C$17)+$C$14 -> 164365.62 | H26: =$C$19 -> 1500000
B27: 4 | C27: =B27+38 -> 42 | D27: =D26*(1+$C$16)+$C$15 -> 253613.88 | E27: =E26*(1+$C$17)+$C$15 -> 268294.1 | F27: =F26*(1+$C$18)+$C$15 -> 283718.02 | G27: =G26*(1+$C$17)+$C$14 -> 181271.21 | H27: =$C$19 -> 1500000
B28: 5 | C28: =B28+38 -> 43 | D28: =D27*(1+$C$16)+$C$15 -> 291294.57 | E28: =E27*(1+$C$17)+$C$15 -> 312074.68 | F28: =F27*(1+$C$18)+$C$15 -> 334252.64 | G28: =G27*(1+$C$17)+$C$14 -> 199360.2 | H28: =$C$19 -> 1500000
B29: 6 | C29: =B29+38 -> 44 | D29: =D28*(1+$C$16)+$C$15 -> 330859.3 | E29: =E28*(1+$C$17)+$C$15 -> 358919.91 | F29: =F28*(1+$C$18)+$C$15 -> 389335.38 | G29: =G28*(1+$C$17)+$C$14 -> 218715.41 | H29: =$C$19 -> 1500000
B30: 7 | C30: =B30+38 -> 45 | D30: =D29*(1+$C$16)+$C$15 -> 372402.26 | E30: =E29*(1+$C$17)+$C$15 -> 409044.3 | F30: =F29*(1+$C$18)+$C$15 -> 449375.56 | G30: =G29*(1+$C$17)+$C$14 -> 239425.49 | H30: =$C$19 -> 1500000
B31: 8 | C31: =B31+38 -> 46 | D31: =D30*(1+$C$16)+$C$15 -> 416022.38 | E31: =E30*(1+$C$17)+$C$15 -> 462677.41 | F31: =F30*(1+$C$18)+$C$15 -> 514819.36 | G31: =G30*(1+$C$17)+$C$14 -> 261585.28 | H31: =$C$19 -> 1500000
B32: 9 | C32: =B32+38 -> 47 | D32: =D31*(1+$C$16)+$C$15 -> 461823.49 | E32: =E31*(1+$C$17)+$C$15 -> 520064.82 | F32: =F31*(1+$C$18)+$C$15 -> 586153.1 | G32: =G31*(1+$C$17)+$C$14 -> 285296.24 | H32: =$C$19 -> 1500000
B33: 10 | C33: =B33+38 -> 48 | D33: =D32*(1+$C$16)+$C$15 -> 509914.67 | E33: =E32*(1+$C$17)+$C$15 -> 581469.36 | F33: =F32*(1+$C$18)+$C$15 -> 663906.88 | G33: =G32*(1+$C$17)+$C$14 -> 310666.98 | H33: =$C$19 -> 1500000
B34: 11 | C34: =B34+38 -> 49 | D34: =D33*(1+$C$16)+$C$15 -> 560410.4 | E34: =E33*(1+$C$17)+$C$15 -> 647172.22 | F34: =F33*(1+$C$18)+$C$15 -> 748658.5 | G34: =G33*(1+$C$17)+$C$14 -> 337813.67 | H34: =$C$19 -> 1500000
B35: 12 | C35: =B35+38 -> 50 | D35: =D34*(1+$C$16)+$C$15 -> 613430.92 | E35: =E34*(1+$C$17)+$C$15 -> 717474.27 | F35: =F34*(1+$C$18)+$C$15 -> 841037.77 | G35: =G34*(1+$C$17)+$C$14 -> 366860.63 | H35: =$C$19 -> 1500000
... B52: 29 | C52: =B52+38 -> 67 | D52: =D51*(1+$C$16)+$C$15 -> 2052004.1 | E52: =E51*(1+$C$17)+$C$15 -> 3037374.1 | F52: =F51*(1+$C$18)+$C$15 -> 4564045.8 | G52: =G51*(1+$C$17)+$C$14 -> 1325382.1 | H52: =$C$19 -> 1500000
B53: PROJECTED BALANCE AT RETIREMENT (AGE 67)
B54: Scenario | C54: Starting Balance | D54: Annual Contribution | E54: Return Rate | F54: Projected Balance | G54: Annual Withdrawal (4%) | H54: Meets Target?
B55: Current Path | C55: =D9 -> 120000 | D55: =C14 -> 5400 | E55: =C17 -> 0.07 | F55: =G52 -> 1325382.1 | G55: =G52*0.04 -> 53015.284 | H55: =IF(F55>=$C$19,"YES","NO") -> NO
B56: Conservative (Recommended) | C56: =D9 -> 120000 | D56: =C15 -> 25000 | E56: =C16 -> 0.05 | F56: =D52 -> 2052004.1 | G56: =D52*0.04 -> 82080.163 | H56: =IF(F56>=$C$19,"YES","NO") -> YES
B57: Base Case (Recommended) | C57: =D9 -> 120000 | D57: =C15 -> 25000 | E57: =C17 -> 0.07 | F57: =E52 -> 3037374.1 | G57: =E52*0.04 -> 121494.96 | H57: =IF(F57>=$C$19,"YES","NO") -> YES
B58: Optimistic (Recommended) | C58: =D9 -> 120000 | D58: =C15 -> 25000 | E58: =C18 -> 0.09 | F58: =F52 -> 4564045.8 | G58: =F52*0.04 -> 182561.83 | H58: =IF(F58>=$C$19,"YES","NO") -> YES
B60: RETIREMENT FUNDING GAP
...

Sheet 8. Portfolio
B2: Investment Portfolio Recommendation
B3: Current vs. recommended asset allocation
B5: CURRENT ASSET ALLOCATION
B6: Asset Class | C6: Current $ | D6: Current % | E6: Target % | F6: Target $
B7: US Large Cap Equity | C7: 45000 | D7: =C7/$C$12 -> 0.375 | E7: 0.45 | F7: =E7*$C$12 -> 54000
B8: US Small/Mid Cap Equity | C8: 15000 | D8: =C8/$C$12 -> 0.125 | E8: 0.15 | F8: =E8*$C$12 -> 18000
B9: International Equity | C9: 10000 | D9: =C9/$C$12 -> 0.083333333 | E9: 0.1 | F9: =E9*$C$12 -> 12000
B10: Bonds / Fixed Income | C10: 35000 | D10: =C10/$C$12 -> 0.29166667 | E10: 0.35 | F10: =E10*$C$12 -> 42000
B11: Cash | C11: 15000 | D11: =C11/$C$12 -> 0.125 | E11: 0.15 | F11: =E11*$C$12 -> 18000
B12: Total | C12: =SUM(C7:C11) -> 120000 | D12: =SUM(D7:D11) -> 1 | E12: =SUM(E7:E11) -> 1.2 | F12: =SUM(F7:F11) -> 144000
B14: REBALANCING ACTIONS
B15: Asset Class | C15: Current $ | D15: Target $ | E15: Difference | F15: Action
B16: =B7 -> US Large Cap Equity | C16: =C7 -> 45000 | D16: =F7 -> 54000 | E16: =D16-C16 -> 9000 | F16: =IF(E16>0,"Buy","Sell") -> Buy
B17: =B8 -> US Small/Mid Cap Equity | C17: =C8 -> 15000 | D17: =F8 -> 18000 | E17: =D17-C17 -> 3000 | F17: =IF(E17>0,"Buy","Sell") -> Buy
B18: =B9 -> International Equity | C18: =C9 -> 10000 | D18: =F9 -> 12000 | E18: =D18-C18 -> 2000 | F18: =IF(E18>0,"Buy","Sell") -> Buy
B19: =B10 -> Bonds / Fixed Income | C19: =C10 -> 35000 | D19: =F10 -> 42000 | E19: =D19-C19 -> 7000 | F19: =IF(E19>0,"Buy","Sell") -> Buy
B20: =B11 -> Cash | C20: =C11 -> 15000 | D20: =F11 -> 18000 | E20: =D20-C20 -> 3000 | F20: =IF(E20>0,"Buy","Sell") -> Buy
B22: RECOMMENDED ETF PORTFOLIO (BASE CASE — 80/20)
B23: Asset Class | C23: Ticker | D23: Expense Ratio | E23: Allocation | F23: Target $
B24: US Total Stock Market | C24: VTI | D24: 0.0003 | E24: 0.4 | F24: =E24*$C$12 -> 48000
B25: US Large Cap Value | C25: VTV | D25: 0.0004 | E25: 0.15 | F25: =E25*$C$12 -> 18000
B26: International Developed | C26: VEA | D26: 0.0006 | E26: 0.15 | F26: =E26*$C$12 -> 18000
B27: Emerging Markets | C27: VWO | D27: 0.0008 | E27: 0.1 | F27: =E27*$C$12 -> 12000
B28: Total Bond Market | C28: BND | D28: 0.0003 | E28: 0.15 | F28: =E28*$C$12 -> 18000
B29: Short-Term Treasury | C29: VGSH | D29: 0.0004 | E29: 0.05 | F29: =E29*$C$12 -> 6000
B30: Total | D30: =SUMPRODUCT(D24:D29,E24:E29) -> 0.000415 | E30: =SUM(E24:E29) -> 1 | F30: =SUM(F24:F29) -> 120000
B32: Weighted Average Expense Ratio: | D32: =D30 -> 0.000415 | E32: (Industry average: ~0.45%)
B34: Chart Data
B35: Asset Class | C35: Current % | D35: Target %
B36: US Equity | C36: =D7+D8 -> 0.5 | D36: =E7+E8 -> 0.6
B37: Intl Equity | C37: =D9 -> 0.083333333 | D37: =E9 -> 0.1
B38: Bonds | C38: =D10 -> 0.29166667 | D38: =E10 -> 0.35
B39: Cash | C39: =D11 -> 0.125 | D39: =E11 -> 0.15

Sheet 9. Insurance
B2: Insurance & Risk Management Review
B3: Coverage gap analysis and recommendations
B5: CURRENT COVERAGE
B6: Coverage Type | C6: Insured | D6: Current Coverage | E6: Annual Premium | F6: Recommended | G6: Gap
B7: Health Insurance | C7: Family | D7: Through employer | E7: 0 | F7: Adequate (employer plan)
B8: Term Life — Sarah | C8: Sarah | D8: 0 | E8: 0 | F8: $750,000, 20-year term
B9: Term Life — Michael | C9: Michael | D9: 50000 | E9: 0 | F9: $500,000, 20-year term
B10: Disability — Sarah | C10: Sarah | D10: 0 | E10: 0 | F10: Own-occupation DI + business overhead
B11: Disability — Michael | C11: Michael | D11: Employer LTD | E11: 0 | F11: Supplemental DI
B12: Auto Insurance | C12: Family | D12: Liability + Collision | E12: 2400 | F12: Increase liability limits
B13: Home Insurance | C13: Family | D13: Standard HO-3 | E13: 1800 | F13: Add scheduled personal property
B14: Umbrella Liability | C14: Family | D14: 0 | E14: 0 | F14: $2M umbrella policy
B15: Business Liability | C15: Business | D15: $1M general liability | E15: 1500 | F15: Increase to $2M + add E&O
B16: Key Person Life | C16: Business | D16: 0 | E16: 0 | F16: $250,000 on Sarah
B17: Total Annual Premium | E17: =SUM(E7:E16) -> 5700
B19: LIFE INSURANCE NEEDS ANALYSIS
B20: Needs Method | C20: Sarah | D20: Michael | E20: Total Need | F20: Current Coverage | G20: Gap
B21: Income replacement (10x annual) | C21: =100000*10 -> 1000000 | D21: =52000*10 -> 520000 | E21: =C21+D21 -> 1520000
B22: Debt payoff | C22: =('6. Debt & Liquidity'!C12)/2 -> 175750 | D22: =('6. Debt & Liquidity'!C12)/2 -> 175750 | E22: =C22+D22 -> 351500
B23: Children's education fund | C23: 80000 | D23: 80000 | E23: =C23+D23 -> 160000
B24: Final expenses | C24: 15000 | D24: 15000 | E24: =C24+D24 -> 30000
B25: Total Life Insurance Need | C25: =SUM(C21:C24) -> 1270750 | D25: =SUM(D21:D24) -> 790750 | E25: =SUM(E21:E24) -> 2061500 | F25: =D8+D9 -> 50000 | G25: =E25-F25 -> 2011500
B27: INSURANCE RECOMMENDATIONS
B28: 1. Purchase $1,250,000 20-year term life on Sarah (est. $60-75/month)
B29: 2. Purchase $750,000 20-year term life on Michael (est. $40-50/month)
B30: 3. Obtain own-occupation disability insurance for Sarah ($4,000/mo benefit, est. $100-150/month)
B31: 4. Add business overhead expense policy ($3,000/mo, est. $60-80/month)
B32: 5. Purchase $2M personal umbrella liability policy (est. $250-350/year)
B33: 6. Increase business liability to $2M and add professional liability coverage
B34: 7. Purchase $250,000 key-person life insurance on Sarah (business-owned)
B35: 8. Review health insurance HDHP/HSA eligibility for additional tax savings

Sheet 10. Tax & Retirement
B2: Tax Planning & Retirement Plan Analysis
B3: Business owner-specific strategies
B5: RETIREMENT PLAN OPTIONS FOR BUSINESS OWNER
B6: Feature | C6: SEP IRA | D6: SIMPLE IRA | E6: Solo 401(k) | F6: Recommendation
B7: Contribution limit (2026) | C7: $69,000 | D7: $16,000 | E7: $69,000 | F7: SEP IRA
B8: Employer contribution | C8: 25% of comp | D8: 3% match | E8: 25% of comp | F8: SEP IRA
B9: Employee contribution | C9: N/A | D9: $16,000 | E9: $23,000 | F9: Solo 401(k)
B10: Employees required to cover | C10: Yes (all eligible) | D10: Yes (all eligible) | E10: No employees | F10: SEP IRA
B11: Setup complexity | C11: Low | D11: Medium | E11: Medium | F11: SEP IRA
B12: Annual admin cost | C12: $0 | D12: $0 | E12: $500-1,000 | F12: SEP IRA
B13: Loan provision | C13: No | D13: No | E13: Yes | F13: Solo 401(k)
B14: Roth option | C14: No | D14: Yes (limited) | E14: Yes | F14: Solo 401(k)
B15: Best for | C15: Simple, flexible | D15: Small team | E15: No employees | F15: SEP IRA
B17: RECOMMENDATION: SEP IRA
B18: Given that East Texas Landscaping & Design LLC has 2 part-time employees, a SEP IRA is the recommended retirement plan. It allows Sarah to contribute up to 25% of her compensation (up to $69,000 for 2026), requires minimal administrative work, and contributions for employees are proportional and straightforward. Note: SEP IRA requires contributions for all eligible employees (age 21+, employed 3 of last 5 years, earning $750+). A Solo 401(k) is not ideal because the business has non-owner employees. The SEP IRA also provides immediate tax deductions and flexibility to adjust contributions based on business performance. Figures are illustrative; consult a tax professional for current IRS limits and eligibility rules.
B22: ANNUAL TAX PROJECTION (CURRENT)
B23: Tax Item | C23: Amount | D23: Notes
B24: Business net income (Sch. C) | C24: 140000 | D24: Revenue $450K - Expenses $310K
B25: Michael's W-2 income | C25: 52000 | D25: Teacher salary
B26: Total gross income | C26: =C24+C25 -> 192000 | D26: Before deductions
B27: 1/2 SE tax deduction | C27: =-C24*0.153/2 -> -10710 | D27: Deductible portion of SE tax
B28: SEP IRA contribution (recommended) | C28: 22500 | D28: 25% of $90K reasonable comp
B29: Michael's 403(b) contribution | C29: 3600 | D29: $300/month
B30: Adjusted Gross Income (AGI) | C30: =C26+C27-C28-C29 -> 155190 | D30: After above-the-line deductions
B31: Standard deduction (MFJ) | C31: 30000 | D31: 2026 estimate
B32: Taxable income | C32: =C30-C31 -> 125190 | D32: Federal taxable income
B33: Federal income tax (est.) | C33: =MAX(C32*0.12-12600,0) -> 2422.8 | D33: 24% bracket effective ~18%
B34: Self-employment tax | C34: =C24*0.153 -> 21420 | D34: Social Security + Medicare
B35: Total estimated tax | C35: =C33+C34 -> 23842.8 | D35: Federal + SE tax
B36: Effective tax rate | C36: =C35/C26 -> 0.12418125 | D36: Overall tax burden
B38: TAX SAVINGS FROM SEP IRA CONTRIBUTION
B39: Metric | C39: Value | D39: Notes
B40: SEP IRA contribution | C40: =C29 -> 3600 | D40: From tax projection above
B41: Tax deduction value (24% bracket) | C41: =C29*0.24 -> 864 | D41: Federal tax savings
B42: SE tax savings | C42: =C29*0.153*0.5 -> 275.4 | D42: Reduction in SE taxable income
B43: Total first-year tax savings | C43: =C41+C42 -> 1139.4 | D43: Combined federal + SE savings
B44: After-tax cost of $22,500 contribution | C44: =C29-C43 -> 2460.6 | D44: Net cost after tax savings
B46: ADDITIONAL TAX STRATEGIES
B47: 1. Implement quarterly estimated tax payments to avoid underpayment penalties
B48: 2. Explore S-Corp election: may reduce SE tax by $8,000-12,000/year if reasonable comp < $140K
...

Sheet 11. Action Plan
B2: Action Plan & Implementation Timeline
B3: Prioritized next steps for the Mitchell household
B5: # | C5: Action Item | D5: Category | E5: Priority | F5: Timeline | G5: Expected Impact
B6: 1 | C6: Open SEP IRA account and make initial $22,500 contribution | D6: Retirement | E6: Critical | F6: Immediate | G6: Tax savings ~$7,200; retirement funding on track
B7: 2 | C7: Increase emergency fund contribution to $2,000/month | D7: Liquidity | E7: Critical | F7: 0-3 months | G7: 6-month fund reached in 15 months
B8: 3 | C8: Allocate $1,500/month to credit card debt paydown | D8: Debt | E8: Critical | F8: 0-6 months | G8: Eliminate $8,500 CC debt in ~6 months
B9: 4 | C9: Apply for $1,250,000 term life insurance on Sarah | D9: Insurance | E9: Critical | F9: 0-3 months | G9: Close $1.25M life insurance gap
B10: 5 | C10: Apply for $750,000 term life insurance on Michael | D10: Insurance | E10: High | F10: 0-3 months | G10: Ensure spouse income replacement
B11: 6 | C11: Obtain disability insurance quotes (own-occupation) | D11: Insurance | E11: High | F11: 3-6 months | G11: Protect $100K+ annual income
B12: 7 | C12: Open 529 plans for both children | D12: College | E12: Medium | F12: 3-6 months | G12: Tax-advantaged college savings
B13: 8 | C13: Rebalance IRA to 80/20 target allocation | D13: Investments | E13: Medium | F13: 3-6 months | G13: Align risk with time horizon
B14: 9 | C14: Purchase $2M personal umbrella liability policy | D14: Insurance | E14: Medium | F14: 6-12 months | G14: Protect assets from lawsuits
B15: 10 | C15: Implement quarterly tax payment system | D15: Tax | E15: High | F15: 6-12 months | G15: Avoid underpayment penalties
B16: 11 | C16: Consult CPA about S-Corp election | D16: Tax | E16: Medium | F16: 6-12 months | G16: Potential SE tax savings $8K-12K/yr
B17: 12 | C17: Develop business succession/exit plan | D17: Business | E17: Medium | F17: 12-24 months | G17: Ensure business continuity
... B20: 15 | C20: Evaluate HSA eligibility through HDHP | D20: Tax | E20: Low | F20: 12+ months | G20: Additional tax-advantaged savings
B22: SUMMARY
B23: Critical actions (0-3 months): SEP IRA setup, emergency fund boost, CC debt paydown, life insurance
B24: High priority (3-12 months): Disability insurance, quarterly tax system, 529 plans, IRA rebalancing
B25: Medium term (12-24 months): S-Corp evaluation, succession planning, estate documents, key-person insurance
B26: Expected outcomes: $25K/yr retirement savings, 6-month emergency fund, $1.25M life insurance coverage, ~$7K tax savings in year 1
